<mujoco model="dog">
  <compiler angle="degree" />
  <option gravity="0 0 -9.81">
    <flag />
  </option>
  <default>
    <geom type="mesh" xyaxes="0 1 0   -1 0 0" />
  </default>
  <asset>
    <mesh name="body" file="body.stl" />
    <mesh name="leg_fl" file="leg_fl.stl" />
    <mesh name="leg_fr" file="leg_fr.stl" />
    <mesh name="leg_br" file="leg_br.stl" />
    <mesh name="leg_bl" file="leg_bl.stl" />
  </asset>
  <worldbody>
    <geom name="floor" type="plane" pos="0 0 0" size="0 0 1" rgba="0.6 0.6 0.6 1" />
    <body name="body" pos="0 0 2">
      <freejoint />
      <geom mesh="body" />
      <body name="leg_fl">
        <geom mesh="leg_fl" />
        <joint name="hip_fl" pos="1.5 0.8 -0.2" axis="0 1 0" limited="true" range="-45 45" />
      </body>
      <body name="leg_fr">
        <geom mesh="leg_fr" />
        <joint name="hip_fr" pos="1.5 -0.8 -0.2" axis="0 1 0" limited="true" range="-45 45" />
      </body>
      <body name="leg_br">
        <geom mesh="leg_br" />
        <joint name="hip_br" pos="-1.5 -0.8 -0.2" axis="0 1 0" limited="true" range="-45 45" />
      </body>
      <body name="leg_bl">
        <geom mesh="leg_bl" />
        <joint name="hip_bl" pos="-1.5 0.8 -0.2" axis="0 1 0" limited="true" range="-45 45" />
      </body>
    </body>
  </worldbody>
  <actuator>
    <position name="hip_fl" joint="hip_fl" ctrllimited="true" ctrlrange="-45 45" kp="100" kv="10" />
    <position name="hip_fr" joint="hip_fr" ctrllimited="true" ctrlrange="-45 45" kp="100" kv="10" />
    <position name="hip_br" joint="hip_br" ctrllimited="true" ctrlrange="-45 45" kp="100" kv="10" />
    <position name="hip_bl" joint="hip_bl" ctrllimited="true" ctrlrange="-45 45" kp="100" kv="10" />
  </actuator>
</mujoco>
